Workbook

Sheet People
A1: Person_ID | B1: Level | C1: Last_name | D1: First_name | E1: Name | F1: Dynasty_or_house | G1: Title_or_role | H1: Name_variants | I1: RKD_Artist_ID | J1: Gender | K1: Date_of_birth | L1: Date_of_birth_precision | M1: Place_of_birth | N1: Date_of_death | O1: Date_of_death_precision | P1: Place_of_death | Q1: Remarks | R1: Profession | S1: Nationality
A2: A001 | B2: A | C2: De Visch | D2: Matthias | E2: =D2&" "&C2 -> Matthias De Visch | H2: Matthijs De Visch; Mathias Fisch | I2: 81220 | K2: 1701-03-22 | L2: probable | M2: Reninge | N2: 1765-04-23 | O2: probable | P2: Bruges | R2: artist
A3: A002 | B3: A | C3: Fernande | D3: Joseph | E3: =D3&" "&C3 -> Joseph Fernande | H3: Jozef Fernande; Jozef Fernandi | I3: 27706 | K3: 1741-10-01 | L3: probable | M3: Bruges | N3: 1799-08-10 | O3: probable | P3: Bruges | R3: artist
A4: A003 | B4: A | C4: Legillon | D4: Jean-François | E4: =D4&" "&C4 -> Jean-François Legillon | H4: Jean-François Le Gillon; Jan Frans Legillon; J.-F. Gillon | I4: 49082 | K4: 1739-09-01 | L4: probable | M4: Bruges | N4: 1797-11-23 | O4: probable | P4: Paris | R4: artist
A5: A004 | B5: A | C5: Cyfflé | D5: Paul-Louis | E5: =D5&" "&C5 -> Paul-Louis Cyfflé | H5: Paulus Gyfflé | K5: 1724-01-06 | L5: probable | M5: Bruges | N5: 1806-08-24 | O5: probable | P5: Ixelles | R5: artist
A6: A005 | B6: A | C6: Verschoot | D6: Bernard | E6: =D6&" "&C6 -> Bernard Verschoot | H6: Bernard Verschooft; Bernardus Verschoot | I6: 80628 | K6: 1727-03-29 | L6: probable | M6: Bruges | N6: 1783-05-01 | O6: probable | P6: Brussels | R6: artist
A7: A006 | B7: A | C7: Pepers (I) | D7: Pieter | E7: =D7&" "&C7 -> Pieter Pepers (I) | H7: Pierre Pepers | I7: 93575 | K7: 1730-10-10 | L7: probable | M7: Bruges | N7: 1785-06-28 | O7: probable | P7: Bruges | R7: artist
A8: A007 | B8: A | C8: De Muynck | D8: Andreas | E8: =D8&" "&C8 -> Andreas De Muynck | H8: Andreas Peter Victor De Muynck; André De Muynck; André Demuinck; Andreas de Muijnch | I8: 333905 | K8: 1737-07-12 | L8: probable | M8: Bruges | N8: 1813-03-14 | O8: probable | P8: Rome | R8: artist
A9: A008 | B9: A | C9: Van Poucke | D9: Karel | E9: =D9&" "&C9 -> Karel Van Poucke | H9: Charles François Van Poucke; Carolus Van Poucke | I9: 420453 | K9: 1740-06-18 | L9: probable | M9: Diksmuide | N9: 1809-11-12 | O9: probable | P9: Ghent | R9: artist
A10: A009 | B10: A | C10: Billoo | D10: Jean | E10: =D10&" "&C10 -> Jean Billoo | H10: Jean Bylloo | K10: 1740 | L10: probable | M10: Bruges | N10: 1798 | O10: probable | P10: Paris | R10: artist
A11: A010 | B11: A | C11: Suvée | D11: Joseph-Benoît | E11: =D11&" "&C11 -> Joseph-Benoît Suvée | I11: 76129 | K11: 1743-01-03 | L11: probable | M11: Bruges | N11: 1807-02-09 | O11: probable | P11: Rome | R11: artist
A12: A011 | B12: A | C12: Malfait | D12: Joseph | E12: =D12&" "&C12 -> Joseph Malfait | H12: Jozef Malfait; Malfette | I12: 516660 | K12: 1754 | L12: probable | M12: Bruges | N12: 1797 | O12: probable | P12: Bruges | R12: artist
A13: A012 | B13: A | C13: Goddyn | D13: Pierre Mathieu | E13: =D13&" "&C13 -> Pierre Mathieu Goddyn | H13: Pieter Matthias Goddyn; Pieter Goddijn | I13: 32281 | K13: 1752-02-25 | L13: probable | M13: Bruges | N13: 1811-02-24 | O13: probable | P13: Bruges | R13: artist
A14: A013 | B14: A | C14: Lauwers | D14: Jacques Jean | E14: =D14&" "&C14 -> Jacques Jean Lauwers | H14: Jacobus Johannes Lauwers | I14: 48384 | K14: 1753-02-26 | L14: probable | M14: Bruges | N14: 1800-12-21 | O14: probable | P14: Amsterdam | R14: artist
A15: A014 | B15: A | C15: De San | D15: Gerardus | E15: =D15&" "&C15 -> Gerardus De San | H15: De San (I); De San senior | I15: 69518 | K15: 1754-05-31 | L15: probable | M15: Bruges | N15: 1830-02-09 | O15: probable | P15: Groningen | R15: artist
A16: A015 | B16: A | C16: van den Berghe | D16: Augustin | E16: =D16&" "&C16 -> Augustin van den Berghe | H16: Berghe Senior; Berghe Père | I16: 7189 | K16: 1756-10-13 | L16: probable | M16: Bruges | N16: 1836-04-11 | O16: probable | P16: Beauvais | R16: artist
A17: A016 | B17: A | C17: van der Donckt | D17: Joseph Octave | E17: =D17&" "&C17 -> Joseph Octave van der Donckt | H17: Joseph Octave van der Donckt; Joseph Angelus Van Der Donckt; Franciscus Josephus Octavius Vander Donckt; François Joseph Octave Van der Donckt | I17: 23694 | K17: 1757-07-30 | L17: probable | M17: Aalst | N17: 1813-08-16 | O17: probable | P17: Bruges | R17: artist
A18: A017 | B18: A | C18: Sénave | D18: Jacques Albert | E18: =D18&" "&C18 -> Jacques Albert Sénave | H18: Jacques Albert Senave | I18: 71949 | K18: 1758-09-12 | L18: probable | M18: Lo | N18: 1823-02-22 | O18: probable | P18: Paris | R18: artist
A19: A018 | B19: A | C19: Van Lede | D19: Maximiliaan Lodewijk | E19: =D19&" "&C19 -> Maximiliaan Lodewijk Van Lede | H19: Maximilien Louis Van Lede | I19: 206220 | K19: 1759-02-18 | L19: probable | M19: Bruges | N19: 1834-07-13 | O19: probable | P19: Bruges | R19: artist
A20: A019 | B20: A | C20: Geysen | D20: Guillielmus | E20: =D20&" "&C20 -> Guillielmus Geysen | H20: Guillaume Pierre Geysen | I20: 363310 | K20: 1761-06-28 | L20: probable | M20: Bruges | N20: 1827-08-21 | O20: probable | P20: Bruges | R20: artist
A21: A020 | B21: A | C21: Ducq | D21: Joseph François | E21: =D21&" "&C21 -> Joseph François Ducq | H21: Jozef Ducq; Giuseppe Ducq; Joseph Le Ducq; Duc; Duck; Duch; Josephus Ducq | I21: 24561 | K21: 1762-09-10 | L21: probable | M21: Ledegem | N21: 1829-04-09 | O21: probable | P21: Bruges | R21: artist
A22: A021 | B22: A | C22: Duvivier | D22: Jean-Bernard | E22: =D22&" "&C22 -> Jean-Bernard Duvivier | H22: Du Vivier | I22: 102854 | K22: 1762-06-22 | L22: probable | M22: Bruges | N22: 1837-11-24 | O22: probable | P22: Paris | R22: artist
A23: A022 | B23: A | C23: Wynckelman | D23: François Jacques | E23: =D23&" "&C23 -> François Jacques Wynckelman | I23: 102125 | K23: 1762-06-29 | L23: probable | M23: Bruges | N23: 1844-01-06 | O23: probable | P23: Bruges | R23: artist
A24: A023 | B24: A | C24: Kinsoen | D24: François Joseph | E24: =D24&" "&C24 -> François Joseph Kinsoen | H24: Franciscus Josephus Kinsoen; Quinsoen; Kinson; Quinsols | I24: 44436 | K24: 1770-02-28 | L24: probable | M24: Bruges | N24: 1839-10-18 | O24: probable | P24: Bruges | R24: artist
A25: A024 | B25: A | C25: De Meulemeester | D25: Joseph Charles | E25: =D25&" "&C25 -> Joseph Charles De Meulemeester | H25: Jozef Karel De Meulemeester; Joseph Van Meulemaester; Demelmestre; Josephus Carolus De Meulemeester; Malmeister; Demeulemeester; Josse de Meulemeester; Van Meulemeester | I25: 20811 | K25: 1771-04-23 | L25: probable | M25: Bruges | N25: 1836-11-07 | O25: probable | P25: Antwerp | R25: artist
A26: A025 | B26: A | C26: Gregorius | D26: Albert Jacques François | E26: =D26&" "&C26 -> Albert Jacques François Gregorius | I26: 33641 | K26: 1774-10-26 | L26: probable | M26: Bruges | N26: 1853-02-25 | O26: probable | P26: Bruges | R26: artist
A27: A026 | B27: A | C27: Calloigne | D27: Jan Robert | E27: =D27&" "&C27 -> Jan Robert Calloigne | H27: Joannes Robertus Calloigne; Jean Robert Calloigne | I27: 298604 | K27: 1775-05-31 | L27: probable | M27: Bruges | N27: 1830-08-26 | O27: probable | P27: Antwerp | R27: artist
A28: A027 | B28: A | C28: Odevaere | D28: Joseph-Denis | E28: =D28&" "&C28 -> Joseph-Denis Odevaere | H28: Joseph Désiré Odevaere; Joseph Dionysius Maria Gislain Odevaere; Odevaëre; Odevar; Odovaere; Oduvard; Odoyaere; Odevaert | I28: 60253 | K28: 1775-12-02 | L28: probable | M28: Bruges | N28: 1830-02-26 | O28: probable | P28: Brussels | R28: artist
A29: A028 | B29: A | C29: Simonau | D29: François | E29: =D29&" "&C29 -> François Simonau | H29: François Simonan; Frans Simoneau | I29: 72687 | K29: 1783-05-26 | L29: probable | M29: Bornem | N29: 1859-11-26 | O29: probable | P29: London | R29: artist
A30: A029 | B30: A | C30: Warlencourt | D30: Joseph | E30: =D30&" "&C30 -> Joseph Warlencourt | H30: Josephus Bruno Warlencourt; Joseph Warlincourt | I30: 82880 | K30: 1784-01-16 | L30: probable | M30: Bruges | N30: 1845-11-07 | O30: probable | R30: artist
A31: A030 | B31: A | C31: Van Acker | D31: Jean-Baptiste | E31: =D31&" "&C31 -> Jean-Baptiste Van Acker | H31: Johannes Baptista van Acker; Jan Van Acker | I31: 79133 | K31: 1794-11-01 | L31: probable | M31: Bruges | N31: 1863-06-15 | O31: probable | R31: artist
A32: A031 | B32: A | C32: De Vlamynck | D32: Pierre-Jean | E32: =D32&" "&C32 -> Pierre-Jean De Vlamynck | H32: Pieter Jan De Vlamijnck; Pieter De Vlaemynck; Petrus Joannes De Vlaemynck | I32: 326619 | K32: 1795-07-01 | L32: probable | M32: Bruges | N32: 1850-03-01 | O32: probable | P32: Bruges | R32: artist
A33: A032 | B33: A | C33: Van den Steene | D33: Auguste | E33: =D33&" "&C33 -> Auguste Van den Steene | H33: Auguste Van De Steene; Augustus Van Den Steene | I33: 79191 | K33: 1803-11-05 | L33: probable | M33: Bruges | N33: 1870-04-06 | O33: probable | P33: Sint-Joost-ten-Node | R33: artist
A34: A033 | B34: A | C34: De Vigne | D34: Pieter | E34: =D34&" "&C34 -> Pieter De Vigne | H34: Pierre De Vigne; Petrus De Vigne-Quyo | I34: 98442 | K34: 1812-07-29 | L34: probable | M34: Ghent | N34: 1877 | O34: probable | P34: Gent | R34: sculptor
A35: A034 | B35: A | C35: Wallays | D35: Edouard-Auguste | E35: =D35&" "&C35 -> Edouard-Auguste Wallays | I35: 82657 | K35: 1813-07-02 | L35: probable | M35: Bruges | N35: 1891-01-28 | O35: probable | P35: Bruges | R35: artist
A36: A035 | B36: A | C36: Cierkens | D36: Jan | E36: =D36&" "&C36 -> Jan Cierkens | I36: 344005 | K36: 1819-05-01 | L36: probable | M36: Bruges | N36: 1852-07-03 | O36: probable | P36: Rome | R36: artist
A37: A036 | B37: A | C37: Dobbelaere | D37: Henri | E37: =D37&" "&C37 -> Henri Dobbelaere | H37: Henricus Dobbelaere; Henri Marie Dobbelaëre | I37: 328006 | K37: 1822-05-25 | L37: probable | M37: Bruges | N37: 1885-01-22 | O37: probable | R37: artist
A38: A037 | B38: A | C38: Copman | D38: Eugène | E38: =D38&" "&C38 -> Eugène Copman | I38: 344032 | K38: 1839 | L38: probable | N38: 1930 | O38: probable | R38: artist
A39: A038 | B39: A | C39: Raoux | D39: Pieter | E39: =D39&" "&C39 -> Pieter Raoux | H39: Pierre Raoux | K39: 1845-09-08 | L39: probable | M39: Assebroek | N39: 6486 | O39: probable | P39: Bruges | R39: artist
A40: A039 | B40: A | C40: Van Hove | D40: Edmond | E40: =D40&" "&C40 -> Edmond Van Hove | H40: Edmond Theodor Van Hove | I40: 40096 | K40: 1851-06-07 | L40: probable | M40: Bruges | N40: 4881 | O40: probable | P40: Bruges | R40: artist
...

Sheet Relations
A1: Relation_ID | B1: Artist_ID | C1: Person_full_name | D1: Associated_person_ID | E1: Associated_person_full_name | F1: Role_of_associated_person | G1: Linked_institution | H1: Relation_source
B2: A001 | C2: =VLOOKUP(B2,People!A$1:E$1000,5,0) -> Matthias De Visch | D2: B155 | E2: =VLOOKUP(D2,People!A$1:E$1000,5,0) -> Jozef van den Kerckhove (I) | F2: teacher | G2: Bruges Royal Academy of Fine Arts
B3: A001 | C3: =VLOOKUP(B3,People!A$1:E$1000,5,0) -> Matthias De Visch | D3: B130 | E3: =VLOOKUP(D3,People!A$1:E$1000,5,0) -> Giambattista Piazetta | F3: teacher
B4: A001 | C4: =VLOOKUP(B4,People!A$1:E$1000,5,0) -> Matthias De Visch | D4: B011 | E4: =VLOOKUP(D4,People!A$1:E$1000,5,0) -> Johannes Beerblock | F4: pupil
B5: A001 | C5: =VLOOKUP(B5,People!A$1:E$1000,5,0) -> Matthias De Visch | D5: B012 | E5: =VLOOKUP(D5,People!A$1:E$1000,5,0) -> Jos. Beke | F5: pupil
B6: A001 | C6: =VLOOKUP(B6,People!A$1:E$1000,5,0) -> Matthias De Visch | D6: A052 | E6: =VLOOKUP(D6,People!A$1:E$1000,5,0) -> Paul De Cock | F6: pupil
B7: A001 | C7: =VLOOKUP(B7,People!A$1:E$1000,5,0) -> Matthias De Visch | D7: B101 | E7: =VLOOKUP(D7,People!A$1:E$1000,5,0) -> Pièrre François Ledoulx | F7: pupil
B8: A001 | C8: =VLOOKUP(B8,People!A$1:E$1000,5,0) -> Matthias De Visch | D8: A007 | E8: =VLOOKUP(D8,People!A$1:E$1000,5,0) -> Andreas De Muynck | F8: pupil
B9: A001 | C9: =VLOOKUP(B9,People!A$1:E$1000,5,0) -> Matthias De Visch | D9: A006 | E9: =VLOOKUP(D9,People!A$1:E$1000,5,0) -> Pieter Pepers (I) | F9: pupil
B10: A001 | C10: =VLOOKUP(B10,People!A$1:E$1000,5,0) -> Matthias De Visch | D10: B057 | E10: =VLOOKUP(D10,People!A$1:E$1000,5,0) -> Jacques De Rijcke | F10: pupil
B11: A001 | C11: =VLOOKUP(B11,People!A$1:E$1000,5,0) -> Matthias De Visch | D11: A010 | E11: =VLOOKUP(D11,People!A$1:E$1000,5,0) -> Joseph-Benoît Suvée | F11: pupil
B12: A001 | C12: =VLOOKUP(B12,People!A$1:E$1000,5,0) -> Matthias De Visch | D12: B151 | E12: =VLOOKUP(D12,People!A$1:E$1000,5,0) -> Antoine Suweyns | F12: pupil
B13: A001 | C13: =VLOOKUP(B13,People!A$1:E$1000,5,0) -> Matthias De Visch | D13: B171 | E13: =VLOOKUP(D13,People!A$1:E$1000,5,0) -> Bernard Verschoot | F13: pupil
B14: A001 | C14: =VLOOKUP(B14,People!A$1:E$1000,5,0) -> Matthias De Visch | D14: B135 | E14: =VLOOKUP(D14,People!A$1:E$1000,5,0) -> Jacobus Prince | F14: pupil | G14: Bruges Royal Academy of Fine Arts | H14: Ledoulx
B15: A001 | C15: =VLOOKUP(B15,People!A$1:E$1000,5,0) -> Matthias De Visch | D15: B078 | E15: =VLOOKUP(D15,People!A$1:E$1000,5,0) -> Jan Garemijn | F15: colleague | G15: Bruges informal De Visch academy | H15: Ledoulx
B16: A001 | C16: =VLOOKUP(B16,People!A$1:E$1000,5,0) -> Matthias De Visch | D16: B110 | E16: =VLOOKUP(D16,People!A$1:E$1000,5,0) -> Eustache Malfait (I) | F16: colleague | G16: Bruges informal De Visch academy | H16: Ledoulx
B17: A001 | C17: =VLOOKUP(B17,People!A$1:E$1000,5,0) -> Matthias De Visch | D17: B109 | E17: =VLOOKUP(D17,People!A$1:E$1000,5,0) -> Ludovicus Malfait | F17: colleague | G17: Bruges informal De Visch academy | H17: Ledoulx
B18: A001 | C18: =VLOOKUP(B18,People!A$1:E$1000,5,0) -> Matthias De Visch | D18: B159 | E18: =VLOOKUP(D18,People!A$1:E$1000,5,0) -> Jean Van Hecke | F18: colleague | G18: Bruges informal De Visch academy | H18: Ledoulx
B19: A001 | C19: =VLOOKUP(B19,People!A$1:E$1000,5,0) -> Matthias De Visch | D19: B165 | E19: =VLOOKUP(D19,People!A$1:E$1000,5,0) -> Pieter van Walleghem | F19: colleague | G19: Bruges informal De Visch academy | H19: Ledoulx
B20: A001 | C20: =VLOOKUP(B20,People!A$1:E$1000,5,0) -> Matthias De Visch | D20: B127 | E20: =VLOOKUP(D20,People!A$1:E$1000,5,0) -> Andreas Petit | F20: colleague | G20: Bruges informal De Visch academy | H20: Ledoulx
B21: A001 | C21: =VLOOKUP(B21,People!A$1:E$1000,5,0) -> Matthias De Visch | D21: B156 | E21: =VLOOKUP(D21,People!A$1:E$1000,5,0) -> Jozef van den Kerckhove (II) | F21: colleague | G21: Bruges informal De Visch academy | H21: Ledoulx
B22: A001 | C22: =VLOOKUP(B22,People!A$1:E$1000,5,0) -> Matthias De Visch | D22: B046 | E22: =VLOOKUP(D22,People!A$1:E$1000,5,0) -> N. de Jhans | F22: colleague | G22: Bruges informal De Visch academy | H22: Ledoulx
B23: A001 | C23: =VLOOKUP(B23,People!A$1:E$1000,5,0) -> Matthias De Visch | D23: B178 | E23: =VLOOKUP(D23,People!A$1:E$1000,5,0) -> Petronelle Yweins | F23: wife | H23: Ledoulx
B24: A001 | C24: =VLOOKUP(B24,People!A$1:E$1000,5,0) -> Matthias De Visch | D24: B096 | E24: =VLOOKUP(D24,People!A$1:E$1000,5,0) -> Joannes Kleyn | F24: model | G24: Bruges informal De Visch academy | H24: Ledoulx
B25: A002 | C25: =VLOOKUP(B25,People!A$1:E$1000,5,0) -> Joseph Fernande | D25: A007 | E25: =VLOOKUP(D25,People!A$1:E$1000,5,0) -> Andreas De Muynck | F25: friend; fellow student; travel companion
B26: A002 | C26: =VLOOKUP(B26,People!A$1:E$1000,5,0) -> Joseph Fernande | D26: A010 | E26: =VLOOKUP(D26,People!A$1:E$1000,5,0) -> Joseph-Benoît Suvée | F26: friend; fellow student; travel companion
B27: A002 | C27: =VLOOKUP(B27,People!A$1:E$1000,5,0) -> Joseph Fernande | D27: B020 | E27: =VLOOKUP(D27,People!A$1:E$1000,5,0) -> Jean Bylloo | F27: friend; fellow student; travel companion
B28: A002 | C28: =VLOOKUP(B28,People!A$1:E$1000,5,0) -> Joseph Fernande | D28: A008 | E28: =VLOOKUP(D28,People!A$1:E$1000,5,0) -> Karel Van Poucke | F28: friend; fellow student; travel companion
B29: A002 | C29: =VLOOKUP(B29,People!A$1:E$1000,5,0) -> Joseph Fernande | D29: B167 | E29: =VLOOKUP(D29,People!A$1:E$1000,5,0) -> Michel-Pierre Vandervoort | F29: rector; mentor | G29: Paris Academy of Saint-Luc
B30: A002 | C30: =VLOOKUP(B30,People!A$1:E$1000,5,0) -> Joseph Fernande | D30: B159 | E30: =VLOOKUP(D30,People!A$1:E$1000,5,0) -> Jean Van Hecke | F30: teacher
B31: A002 | C31: =VLOOKUP(B31,People!A$1:E$1000,5,0) -> Joseph Fernande | D31: B168 | E31: =VLOOKUP(D31,People!A$1:E$1000,5,0) -> Claude-Louis Vassé | F31: teacher; studio master | G31: Paris Royal Academy of Fine Arts
B32: A002 | C32: =VLOOKUP(B32,People!A$1:E$1000,5,0) -> Joseph Fernande | D32: B053 | E32: =VLOOKUP(D32,People!A$1:E$1000,5,0) -> Florimond-Claude de Mercy-Argenteau | F32: benefactor
B33: A002 | C33: =VLOOKUP(B33,People!A$1:E$1000,5,0) -> Joseph Fernande | D33: B060 | E33: =VLOOKUP(D33,People!A$1:E$1000,5,0) -> Georges-Adam de Starhemberg | F33: benefactor
B34: A002 | C34: =VLOOKUP(B34,People!A$1:E$1000,5,0) -> Joseph Fernande | D34: B120 | E34: =VLOOKUP(D34,People!A$1:E$1000,5,0) -> Maria Theresa of Austria | F34: benefactor
B35: A002 | C35: =VLOOKUP(B35,People!A$1:E$1000,5,0) -> Joseph Fernande | D35: B115 | E35: =VLOOKUP(D35,People!A$1:E$1000,5,0) -> René Milot | F35: travel companion
B36: A002 | C36: =VLOOKUP(B36,People!A$1:E$1000,5,0) -> Joseph Fernande | D36: B001 | E36: =VLOOKUP(D36,People!A$1:E$1000,5,0) -> Alexandre Albani | F36: benefactor
B37: A002 | C37: =VLOOKUP(B37,People!A$1:E$1000,5,0) -> Joseph Fernande | D37: B176 | E37: =VLOOKUP(D37,People!A$1:E$1000,5,0) -> Anton von Maron | F37: mentor
B38: A002 | C38: =VLOOKUP(B38,People!A$1:E$1000,5,0) -> Joseph Fernande | D38: B118 | E38: =VLOOKUP(D38,People!A$1:E$1000,5,0) -> Charles Joseph Natoire | F38: director; mentor | G38: Rome Académie de France
B39: A002 | C39: =VLOOKUP(B39,People!A$1:E$1000,5,0) -> Joseph Fernande | D39: B173 | E39: =VLOOKUP(D39,People!A$1:E$1000,5,0) -> Joseph Marie Vien (I) | F39: director; mentor | G39: Rome Académie de France
B40: A003 | C40: =VLOOKUP(B40,People!A$1:E$1000,5,0) -> Jean-François Legillon | D40: B006 | E40: =VLOOKUP(D40,People!A$1:E$1000,5,0) -> Jean-Jacques Bachelier | F40: teacher | G40: Paris Royal Academy of Fine Arts
...

Sheet Travels
A1: Travel_ID | B1: Person_ID_(traveller) | C1: Main_travel_destination | D1: Arrival_date | E1: Arrival_date_precision | F1: Arrival_date_source | G1: Confirmed_presence | H1: Confirmed_presence_source | I1: End_date | J1: End_date_precision | K1: End_date_source | L1: Travel_duration | M1: Secondary_places | N1: Linked_chronology | O1: Travel_remark | P1: Financial_means_of_travel | Q1: Artwork_ID | R1: Event_note
A2: E001 | B2: A001 | C2: Paris | D2: 1723 | E2: probable | F2: Ledoulx; Weale | I2: 1723 | J2: probable | P2: unknown
A3: E002 | B3: A001 | C3: Rome | D3: 1724 | E3: N/A | F3: N/A | I3: 1732 | J3: probable | K3: Ledoulx | M3: Venice; Parma; Piacenza | N3: unknown; unknown; unknown | P3: unknown
A4: E003 | B4: A002 | C4: Paris | D4: 1763 | E4: certain | F4: Ledoulx; Jacques 1957 | I4: 1772 | J4: certain | K4: Jacques 1957 | P4: unknown
A5: E004 | B5: A002 | C5: Rome | D5: 1772-12-06 | E5: certain | F5: Jacques 1957 | I5: 1776 | J5: certain | K5: Jacques 1957 | M5: Naples; Florence; Trieste; Venice | N5: unknown; unknown; unknown | P5: state-funded (yearly pension)
A6: E005 | B6: A003 | C6: Rouen | D6: 1760-05-01 | E6: probable | F6: Legillon; Weale; De Wallens | I6: 1762 | J6: probable | K6: Ledoulx; Weale; De Wallens | P6: unknown
A7: E006 | B7: A003 | C7: Rouen | D7: 1763-07-01 | E7: probable | F7: Ledoulx; Delepierre; Weale | I7: 1766-11-01 | J7: probable | K7: Ledoulx; Weale | P7: unknown
A8: E007 | B8: A003 | C8: Paris | D8: 1767-05-01 | E8: probable | F8: Ledoulx; Weale | G8: 1767 | H8: Réau; De Wallens | I8: 1768-08-01 | J8: probable | K8: Ledoulx; Weale; De Wallens | M8: Marseille; Toulouse | N8: after; after | P8: unknown
A9: E008 | B9: A003 | C9: Marseille | D9: 1769-08-01 | E9: probable | F9: Ledoulx | I9: 1770-09-15 | J9: probable | K9: Ledoulx | P9: unknown
A10: E009 | B10: A003 | C10: Rome | D10: 1770-09-30 | E10: certain | F10: Ledoulx; Delepierre; Weale; De Wallens | G10: 1771; 1772 | H10: Coekelberghs | I10: 1772-04-01 | J10: certain | K10: Ledoulx; Delepierre; Weale; De Wallens | M10: Civitavecchia | N10: unknown | O10: After Rome, he is said to have travelled across Italy until 1774. | P10: unknown
A11: E010 | B11: A003 | C11: Paris | D11: 1782-09-01 | E11: certain | F11: Ledoulx; Delepierre; Weale; De Wallens | I11: 1797-11-23 | J11: certain | K11: Ledoulx; Delepierre; Weale | O11: Besides these years-long stays, he also travelled to Paris (FR) in 1776 and 1779 and to Switzerland in 1779-1780, and visited Fontainebleau (FR) and Normandy (FR). | P11: unknown
A12: E011 | B12: A004 | C12: Paris | D12: 1741-05-01 | E12: probable | F12: Ledoulx | I12: 1746 | J12: probable | K12: Grove Art; Bénézit; Ledoulx insinuates 1748 | P12: unknown
A13: E012 | B13: A004 | C13: Lunéville | D13: 1746 | E13: probable | F13: Grove Art; Bénézit; Ledoulx insinuates 1748 | I13: 1777 | J13: probable | K13: Ledoulx | P13: unknown
A14: E013 | B14: A005 | C14: Paris | D14: 1754 | E14: inferred | F14: RKD; shortly after 1749 according to Ledoulx | G14: 1754; 1755; 1756; 1757 | H14: De Wallens | I14: 1757 | J14: inferred | K14: RKD | P14: unknown
A15: E014 | B15: A005 | C15: Rome | D15: 1757 | E15: estimate | F15: RKD | I15: 1765 | J15: certain | K15: Coekelberghs; De Wallens | M15: Napels; Venice | N15: unknown; unknown | P15: unknown
A16: E015 | B16: A006 | C16: Paris | D16: 1751 | E16: probable | F16: Ledoulx; Devliegher | I16: 1759 | J16: probable | K16: Ledoulx; Devliegher | P16: unknown
A17: E016 | B17: A007 | C17: Paris | D17: 1763 | E17: certain | F17: Ledoulx | G17: 1766 | H17: Réau; De Wallens | I17: 1767 | J17: inferred | P17: unknown
A18: E017 | B18: A007 | C18: Rome | D18: 1768 | E18: inferred | G18: 1769 | H18: Coekelberghs | I18: 1813 | J18: certain | P18: unknown
A19: E018 | B19: A008 | C19: Paris | D19: 1763 | E19: certain | F19: Ledoulx | G19: 1765 | H19: Réau | I19: 1767 | J19: estimate | P19: state-funded (yearly pension)
A20: E019 | B20: A008 | C20: Rome | D20: 1768 | E20: certain | F20: Bussers | I20: 1774 | J20: certain | K20: Ledoulx | M20: Naples | N20: after | O20: After his Roman stay, he likely travelled across Italy, since he is reported to have left Italy only in 1776. | P20: unknown
A21: E020 | B21: A008 | C21: Rome | D21: 1776 | E21: probable | F21: Ledoulx | I21: 1778 | J21: probable | K21: Ledoulx; Delepierre mentions 1779 | P21: unknown
A22: E021 | B22: A009 | C22: Paris | D22: 1763 | E22: certain | F22: Ledoulx | I22: 1798 | J22: probable | K22: Ledoulx | P22: unknown
A23: E022 | B23: A010 | C23: Paris | D23: 1763 | E23: certain | F23: Ledoulx | I23: 1772 | J23: uncertain | P23: unknown
A24: E023 | B24: A010 | C24: Rome | D24: 1772-10-01 | E24: probable | F24: Join-Lambert & Leclair | I24: 1777 | J24: certain | K24: Artl@s | M24: Naples; Taormina; Catania; Syracuse; Agrigento; Segesta; Valletta | N24: during; during; during; during; during; during; during | O24: During his Roman stay, he travelled to Sicily and Malta at the invitation of Pierre Marie Gaspard Grimod, Count of Orsay, from May to September 1777. | P24: state-funded (Prix de Rome)
A25: E024 | B25: A010 | C25: Paris | D25: 1778-08-01 | E25: probable | F25: Ledoulx | I25: 1801-10-01 | J25: probable | K25: Ledoulx; Weale | P25: unknown
A26: E025 | B26: A010 | C26: Rome | D26: 1801-11-24 | E26: certain | F26: Join-Lambert & Leclair: Brunel & Julia; 1802 wordt soms opgegeven maar is foutief | I26: 1807-02-09 | J26: certain | K26: death | P26: state-funded
A27: E026 | B27: A011 | C27: Paris | D27: 1766 | E27: probable | F27: Ledoulx | I27: 1767 | J27: certain | K27: Coekelberghs | P27: unknown
A28: E027 | B28: A011 | C28: Rome | D28: 1767-09-01 | E28: certain | F28: Coekelberghs | G28: 1771 | H28: Coekelberghs | I28: 1775 | J28: estimate | K28: Ledoulx | P28: self-funded
A29: E028 | B29: A012 | C29: Paris | D29: 1772 | E29: probable | F29: Ledoulx; De Wallens | I29: 1779 | J29: probable | K29: De Wallens | P29: unknown
A30: E029 | B30: A012 | C30: Rome | D30: 1779 | E30: certain | F30: Coekelberghs; Kerremans | G30: 1779; 1781 | H30: Coekelberghs; studies Prentenkabinet | I30: 12/1783 of 01/1784 | J30: inferred | K30: Delepierre; Weale; Coekelberghs (maakte foutje) | O30: Note that the artist participated in a competition of the Parma Academy and owned volcanic stones from Naples, though this does not necessarily imply that he visited Parma or Naples. | P30: unknown
A31: E030 | B31: A013 | C31: Rome | D31: 1775 | E31: estimate | F31: Coekelberghs; De Wallens; RKD mentions 1776 | I31: 1776 | J31: uncertain | K31: RKD | P31: self-funded
A32: E031 | B32: A013 | C32: Paris | D32: 1777 | E32: estimate | F32: Jacobs; De Wallens | G32: 1779 | H32: Réau; De Wallens | I32: 1780 | J32: uncertain | K32: RKD | P32: unknown
A33: E032 | B33: A013 | C33: Amsterdam | D33: 1780 | E33: uncertain | F33: RKD | G33: 1788; 1789 | H33: Ledoulx | I33: 1800 | J33: certain | M33: The Hague | N33: during | P33: patron-funded
A34: E033 | B34: A014 | C34: Rome | D34: 1781-11-01 | E34: certain | F34: Ledoulx; Coekelberghs | I34: 1784 | J34: inferred | K34: Ledoulx | O34: Note that the artist participated in competitions of the Parma Academy, though this does not necessarily imply that he visited Parma. | P34: unknown
A35: E034 | B35: A014 | C35: Groningen | D35: 1794 | E35: certain | F35: Ledoulx | I35: 1830 | J35: probable | P35: unknown
A36: E035 | B36: A015 | C36: Paris | D36: 1779 | E36: probable | F36: Ledoulx | G36: 1779 | H36: Réau | I36: 1790 | J36: probable | K36: Ledoulx; 1791 according to RKD | M36: Rotterdam; Gouda | N36: during | P36: unknown
A37: E036 | B37: A015 | C37: Beauvais | D37: 1796 | E37: probable | F37: Ledoulx | I37: 1836 | J37: uncertain | K37: RKD | P37: unknown
A38: E037 | B38: A016 | C38: Marseille | D38: 1780 | E38: probable | F38: Ledoulx | I38: 1782 | J38: before (inferred) | K38: RKD claims 1780 | P38: unknown
A39: E038 | B39: A016 | C39: Paris | D39: 1782 | E39: probable | F39: Kerremans; RKD; Janssens & Knolle 2007 | I39: 1785 | J39: probable | K39: Kerremans; RKD; Janssens & Knolle 2007 | P39: unknown
A40: E039 | B40: A016 | C40: Rome | D40: 1790 | E40: inferred | F40: Ledoulx; Delepierre; Weale; Coekelberghs claims 1789 | I40: 1791 | J40: probable | K40: Ledoulx; Delepierre; Weale; Coekelberghs | P40: unknown
...

Sheet Places
A1: Place_ID | B1: Place_name | C1: Latitude | D1: Longitude
A2: P001 | B2: Aalst | C2: 50.938323 | D2: 4.039215
A3: P002 | B3: Amsterdam | C3: 52.378 | D3: 4.9
A4: P003 | B4: Angers | C4: 47.470176 | D4: -0.554217
A5: P004 | B5: Antwerp | C5: 51.22111 | D5: 4.399708
A6: P005 | B6: Antwerpen | C6: 51.22111 | D6: 4.399708
A7: P006 | B7: Assebroek | C7: 51.19554 | D7: 3.253053
A8: P007 | B8: Bangor (Me) | C8: 44.801616 | D8: -68.771305
A9: P008 | B9: Beauvais | C9: 49.4312 | D9: 2.08358
A10: P009 | B10: Bergues | C10: 50.968155 | D10: 2.43302
A11: P010 | B11: Boothbay Harbor (Me) | C11: 43.851667 | D11: -69.627778
A12: P011 | B12: Bornem | C12: 51.095301 | D12: 4.234131
A13: P012 | B13: Boston | C13: 42.345697 | D13: -71.035864
... A54: P053 | B54: Weerde | C54: 50.97345 | D54: 4.47487
